Workbook

Sheet Summary
A1: Platform Resource Calculator Summary
A2: Calculates CPU, RAM and Storage required for Platform related modules
A5: Data to be provided by country
A6: Key Inputs | B6: Values
A7: Total Population to be Registered | B7: 100000000 | C7: Note: Few additional assumptions have been used to calculate below estimates. Check respective sheets for detailed information.
A8: Number of registration client devices | B8: 5000
A9: Typical Number of registration per day per device expected | B9: 50
A10: Avg Authentication per day as % | B10: 0.1
A14: Scenario | B14: Avg Daily Load | C14: Peak Load ( TPS ) | D14: vCPU | E14: RAM (GB) | F14: pods | G14: Note: These calculations represent approximate estimates derived from our testing. Actual performance in your environment may vary depending on factors such as load, infrastructure capacity, hardware, and data characteristics.
A15: Registrations Upload & SyncData | B15: ='Registrations Upload & SyncData'!B17 -> 250000 | C15: ='Registrations Upload & SyncData'!B19 -> 84 | D15: ='Registrations Upload & SyncData'!E29 -> 250 | E15: ='Registrations Upload & SyncData'!F29 -> 674 | F15: ='Registrations Upload & SyncData'!G29 -> 102
A16: Authentication | B16: =IDAuthentication!B16 -> 10000000 | C16: =IDAuthentication!B18 -> 223 | D16: =IDAuthentication!E27 -> 217 | E16: =IDAuthentication!F27 -> 697 | F16: =IDAuthentication!G27 -> 87
A17: Total Resources required | D17: =SUM(D15:D16) -> 467 | E17: =SUM(E15:E16) -> 1371 | F17: =SUM(F15:F16) -> 189
A19: Duration for registration to complete (in working days) | B19: ='Registrations Upload & SyncData'!B27 -> 400
A24: Note: The TPS for each calculator is arrived based on some assumed weightage between different types of transaction. For more details on workload model in the Performance Report

Sheet Registrations Upload & SyncData
A1: Registration Resource Calculator
A2: Calculates CPU, RAM and Storage required for New Registration Upload & Sync Data
A5: Data to be provided by country
A6: Key Inputs | B6: Values
A7: Total Population to be Registered | B7: 100000000 | C7: Should be updated in Summary Sheet
A8: Number of registration client devices | B8: 5000
A9: Typical Number of registration per day per device expected | B9: 50
A11: Data based on Industry standards
A12: Additional Assumptions | B12: Values
A13: Number of Hours in upload window | B13: 1 | C13: Should be updated as per Country's planned operational requirements
A14: Peak day multiplier | B14: 1.2
A16: Calculation based on Key Input and Assumptions | B16: Values
A17: Typical Number of Registration Upload per day | B17: =B8*B9 -> 250000
A18: Peak Daily Upload (Daily Load X Peak day multiplier) | B18: =B17*B14 -> 300000
A19: Peak Hour Upload per second - TPS | B19: =CEILING(B18/B13/3600,1) -> 84
A21: Performance Observed during Internal Test
A22: Performance Run TPS | B22: 22.5
A24: Multiplying Factor required to match the peak Processing load | B24: =CEILING(B19/B22,1) -> 4
A27: Duration for registration to complete (in working days) | B27: =CEILING(B7/B17,1) -> 400
E28: vCPU | F28: RAM | G28: pods
A29: Total Resources required | E29: =E53 -> 250 | F29: =F53 -> 674 | G29: =G53 -> 102
A31: Calculation
B32: Resource used in Internal Test | E32: Resources Required
A33: Services | B33: vCPU per pod | C33: RAM (GB) per pod | D33: ="Pods required for "&B22&" TPS" -> Pods required for 22.5 TPS | E33: Total vCPU | F33: Total RAM (GB) | G33: Total pods required for Peak hour
A37: registration-processor-stage-group-1 | B37: 1 | C37: 1 | D37: 2 | E37: =$G37*B37 -> 8 | F37: =$G37*C37 -> 8 | G37: =$B$24*D37 -> 8
A38: registration-processor-registration-status-service | B38: 0.7 | C38: 1.5 | D38: 2 | E38: =$G38*B38 -> 5.6 | F38: =$G38*C38 -> 12 | G38: =$B$24*D38 -> 8
A39: registration-processor-registration-transaction-service | B39: 1 | C39: 5 | D39: 2 | E39: =$G39*B39 -> 8 | F39: =$G39*C39 -> 40 | G39: =$B$24*D39 -> 8
A40: kernel-Sync Data | B40: 2 | C40: 2.5 | D40: 3 | E40: =$G40*B40 -> 24 | F40: =$G40*C40 -> 30 | G40: =$B$24*D40 -> 12
A41: keymanager-Key Manager | B41: 2 | C41: 6 | D41: 4 | E41: =$G41*B41 -> 32 | F41: =$G41*C41 -> 96 | G41: =$B$24*D41 -> 16
A42: KERNEL-MASTERDATA | B42: 0.5 | C42: 2.25 | D42: 2 | E42: =$G42*B42 -> 4 | F42: =$G42*C42 -> 18 | G42: =$B$24*D42 -> 8
A43: KERNEL-AUDITMANAGER | B43: 2 | C43: 5 | D43: 2 | E43: =$G43*B43 -> 16 | F43: =$G43*C43 -> 40 | G43: =$B$24*D43 -> 8
A44: KERNEL-AUTHMANAGER | B44: 1 | C44: 5 | D44: 3 | E44: =$G44*B44 -> 12 | F44: =$G44*C44 -> 60 | G44: =$B$24*D44 -> 12
A45: kafka | B45: 2 | C45: 5 | D45: 5 | E45: =$G45*B45 -> 40 | F45: =$G45*C45 -> 100 | G45: =$B$24*D45 -> 20
A46: Redis (Standalone) | E46: =$G46*B46 -> 0 | F46: =$G46*C46 -> 0 | G46: 1
A47: PostGres (Standalone) | E47: =$B$24*B47 -> 0 | F47: =$G47*C47 -> 0 | G47: 1
E48: =SUM(E37:E47) -> 149.6 | F48: =SUM(F37:F47) -> 404 | G48: =SUM(G37:G47) -> 102
A49: Buffers
A50: A - Monitoring, Logging and alerts.( 20% of Total CPU & memory) | E50: =E48*0.2 -> 29.92 | F50: =F48*0.2 -> 80.8
A51: B - Kubernetes infra. (30% of A) | E51: =ROUND((E48+E50)*0.3,2) -> 53.86 | F51: =(F48+F50)*0.3 -> 145.44
A52: C - Buffer in the system. (30% of B) | E52: =ROUND((E51*0.3),2) -> 16.16 | F52: =ROUND((F51*0.3),2) -> 43.63
...

Sheet IDAuthentication
A1: ID Authentication Resource Calculator
A2: Calculates CPU, RAM and Storage required for ID Authentication
A5: Data to be provided by country
A6: Key Inputs | B6: Values
A7: Total population having National Id | B7: =Summary!B7 -> 100000000 | C7: Should be updated in Summary Sheet
A8: Avg Authentication per day as % | B8: =Summary!B10 -> 0.1
A10: Data based on Industry standards
A11: Additional Assumptions | B11: Values
A12: Peak Hour Authentication per day as % of daily | B12: 0.08 | C12: Should be updated as per Country's planned operational requirements
A14: Calculation based on Key Input and Assumptions | B14: Values
A15: Total Population using National ID for authentication | B15: =B7 -> 100000000
A16: Avg Authentication per day | B16: =B7*B8 -> 10000000
A17: Peak Authentication per hour | B17: =B16*B12 -> 800000
A18: No. of users using the system in any given second during the peak hour - TPS | B18: =CEILING(B17/3600,1) -> 223
A20: Performance Observed during Internal Test
A21: Performance Run TPS | B21: 50
A23: Factor required to match the expected peak hour TPS | B23: =CEILING(B18/B21,1) -> 5
E26: vCPU | F26: RAM | G26: pods
A27: Total Resources required | E27: =E48 -> 217 | F27: =F48 -> 697 | G27: =G48 -> 87
A29: Calculation
B30: Resource used in Internal Test | E30: Resources Required
A31: Services | B31: vCPU per pod | C31: RAM (GB) per pod | D31: ="Pods required for "&B21&" TPS" -> Pods required for 50 TPS | E31: Total vCPU | F31: Total RAM (GB) | G31: Total pods required for Peak hour
A35: ida-IDA-AUTH | B35: 2 | C35: 5 | D35: 4 | E35: =$G35*B35 -> 40 | F35: =$G35*C35 -> 100 | G35: =$B$23*D35 -> 20
A36: ida-IDA-OTP | B36: 0.5 | C36: 4 | D36: 2 | E36: =$G36*B36 -> 5 | F36: =$G36*C36 -> 40 | G36: =$B$23*D36 -> 10
A37: bisosdk-biosdk-service | B37: 1.5 | C37: 4 | D37: 3 | E37: =$G37*B37 -> 22.5 | F37: =$G37*C37 -> 60 | G37: =$B$23*D37 -> 15
A38: kernel-NOTIFIER | B38: 1.5 | C38: 5 | D38: 3 | E38: =$G38*B38 -> 22.5 | F38: =$G38*C38 -> 75 | G38: =$B$23*D38 -> 15
A39: kernel-OTPMANAGER | B39: 0.5 | C39: 3.1 | D39: 3 | E39: =$G39*B39 -> 7.5 | F39: =$G39*C39 -> 46.5 | G39: =$B$23*D39 -> 15
A40: kernel-AUDITMANAGER | B40: 2 | C40: 5 | D40: 2 | E40: =$G40*B40 -> 20 | F40: =$G40*C40 -> 50 | G40: =$B$23*D40 -> 10
A41: Redis (Standalone) | B41: 4 | C41: 15 | D41: 1 | E41: =$G41*B41 -> 4 | F41: =$G41*C41 -> 15 | G41: 1
A42: PostGres (Standalone) | B42: 8 | C42: 31 | D42: 1 | E42: =$G42*B42 -> 8 | F42: =$G42*C42 -> 31 | G42: 1
E43: =SUM(E35:E42) -> 129.5 | F43: =SUM(F35:F42) -> 417.5 | G43: =SUM(G35:G42) -> 87
A44: Buffers
A45: A - Monitoring, Logging and alerts. (20% of Total CPU & memory) | E45: =E43*0.2 -> 25.9 | F45: =F43*0.2 -> 83.5
A46: B - Kubernetes infra. (30% of A) | E46: =ROUND((E43+E45)*0.3,2) -> 46.62 | F46: =(F43+F45)*0.3 -> 150.3
A47: C - Buffer in the system. (30% of B) | E47: =ROUND((E46*0.3),2) -> 13.99 | F47: =ROUND((F46*0.3),2) -> 45.09
A48: Total Resources required | E48: =CEILING((SUM(E43:E47)),1) -> 217 | F48: =CEILING(SUM(F43:F47),1) -> 697 | G48: =CEILING((SUM(G35:G42)),1) -> 87
E49: VCPU | F49: RAM | G49: pods
A51: Note: Data storage requirement is not included
